Workbook
Name Scenario: Inputs!$B$3
Name CorpCost2025: Inputs!$B$6
Name CorpInfl: Inputs!$B$7
Name TaxRate: Inputs!$B$8
Name NWCPct: Inputs!$B$9
Name PPE2025: Inputs!$B$10
Name DA2025: Inputs!$B$11
Name AssetLife: Inputs!$B$12
Name WACC: Inputs!$B$13
Name VarPct: Inputs!$B$14
Name VarAmt: Inputs!$B$15

Sheet Cover
A1: Granite Peak Materials Group: Five-Year Strategic Plan, Consolidation & CAPEX Model
A2: Illustrative company and figures (fictional). Macro data is real, from FRED (Federal Reserve Bank of St. Louis).
A4: Purpose | B4: Consolidates four operating companies into the FY2027 annual budget and FY2027-FY2031 strategic plan, tracks FY2026 CAPEX against budget, evaluates growth projects and builds free cash flow.
A5: Scenario | B5: Change Inputs!B3 (1 = Base, 2 = Downside, 3 = Upside). Every sheet recalculates.
A6: Update the forecast | B6: Enter new FY2026 year-to-date CAPEX on Inputs and Projects, refresh macro data on Macro (FY2026 driver growth links to the year-to-date change).
A7: Conventions | B7: Blue = input. Black = formula. $ millions unless stated. Capex variance: + = under budget.
A9: Sheets
A10: Inputs | B10: Scenario selector, group assumptions, operating company drivers, price growth, scenario adjustments
A11: Macro | B11: FRED housing starts, construction spending, highway spending, mortgage rate, materials PPI; plan driver growth
A12: Projects | B12: Growth CAPEX register: approved vs. forecast, FY2026 budget vs. forecast, status, NPV / IRR / payback
A13: OpCo_Plan | B13: Volume x price build by operating company, EBITDA, maintenance and growth CAPEX
A14: Consolidation | B14: Group P&L with intercompany eliminations, D&A and PP&E roll-forward, taxes, working capital, free cash flow
A15: Capex_Report | B15: FY2026 CAPEX budget vs. YTD vs. forecast by operating company with flags; five-year CAPEX plan
A16: Board_Summary | B16: Headline KPIs for the active scenario and the FY2026-FY2031 EBITDA bridge
A17: Checks | B17: Integrity checks rolled up to one ALL CHECKS PASS cell

Sheet Inputs
A1: Inputs
A3: Active scenario (1 Base, 2 Downside, 3 Upside) | B3: 1 | C3: =CHOOSE(Scenario,"Base","Downside","Upside")
A5: Group assumptions
A6: Corporate costs FY2025A ($M) | B6: 120
A7: Corporate cost inflation | B7: 0.035
A8: Cash tax rate | B8: 0.24
A9: Net working capital, % of revenue | B9: 0.14
A10: Net PP&E, end FY2025 ($M) | B10: 7800
A11: D&A FY2025A ($M) | B11: 420
A12: Average asset life (years); D&A = opening PP&E / life | B12: 18
A13: WACC / hurdle rate for growth projects | B13: 0.085
A14: CAPEX variance flag: % threshold | B14: 0.1
A15: CAPEX variance flag: $M threshold | B15: 5
A18: Operating company drivers (FY2025A base)
A19: Operating company | B19: Unit | C19: Volume driver | D19: Elasticity to driver | E19: Base volume growth | F19: Volume FY2025A (M) | G19: Price / unit FY2025A ($) | H19: Variable cost / unit FY2025A ($) | I19: Fixed costs FY2025A ($M) | J19: Variable cost inflation | K19: Fixed cost inflation | L19: Maintenance capex % revenue | M19: Capex FY2025A ($M) | N19: Intercompany sales % revenue | O19: FY2026 maint. capex budget ($M) | P19: FY2026 maint. capex YTD Sep ($M)
A20: Aggregates | B20: tons | C20: TLHWYCONS | D20: 0.6 | E20: 0.005 | F20: 95 | G20: 16.5 | H20: 8.2 | I20: 260 | J20: 0.042 | K20: 0.035 | L20: 0.06 | M20: 118 | N20: 0.1 | O20: 104 | P20: 71.5
A21: Cement | B21: tons | C21: TTLCONS | D21: 0.8 | E21: 0 | F21: 9.5 | G21: 155 | H21: 88 | I21: 180 | J21: 0.036 | K21: 0.035 | L21: 0.07 | M21: 121 | N21: 0.18 | O21: 112 | P21: 76
A22: Ready-Mix Concrete | B22: cubic yards | C22: HOUST | D22: 0.7 | E22: 0 | F22: 14 | G22: 165 | H22: 128 | I22: 290 | J22: 0.036 | K22: 0.035 | L22: 0.03 | M22: 64 | N22: 0 | O22: 72 | P22: 55.2
A23: Asphalt & Paving | B23: tons | C23: TLHWYCONS | D23: 0.9 | E23: 0 | F23: 11 | G23: 82 | H23: 63 | I23: 95 | J23: 0.036 | K23: 0.035 | L23: 0.04 | M23: 33 | N23: 0 | O23: 40 | P23: 27.1
A26: Price growth by year
A27: Operating company | D27: FY2026 | E27: FY2027 | F27: FY2028 | G27: FY2029 | H27: FY2030 | I27: FY2031
A28: Aggregates | D28: 0.06 | E28: 0.055 | F28: 0.05 | G28: 0.045 | H28: 0.04 | I28: 0.04
A29: Cement | D29: 0.02 | E29: 0.03 | F29: 0.035 | G29: 0.035 | H29: 0.03 | I29: 0.03
A30: Ready-Mix Concrete | D30: 0.03 | E30: 0.035 | F30: 0.035 | G30: 0.035 | H30: 0.03 | I30: 0.03
A31: Asphalt & Paving | D31: 0.03 | E31: 0.035 | F31: 0.035 | G31: 0.03 | H31: 0.03 | I31: 0.03
A34: Scenario adjustments (plan years FY2027-FY2031)
A35: Volume growth adjustment | D35: FY2026 | E35: FY2027 | F35: FY2028 | G35: FY2029 | H35: FY2030 | I35: FY2031
A36: Base | D36: 0 | E36: 0 | F36: 0 | G36: 0 | H36: 0 | I36: 0
A37: Downside | D37: 0 | E37: -0.04 | F37: -0.03 | G37: -0.01 | H37: 0 | I37: 0
A38: Upside | D38: 0 | E38: 0.015 | F38: 0.02 | G38: 0.01 | H38: 0.01 | I38: 0.01
A39: Active | D39: =CHOOSE(Scenario,D36,D37,D38) | E39: =CHOOSE(Scenario,E36,E37,E38) | F39: =CHOOSE(Scenario,F36,F37,F38) | G39: =CHOOSE(Scenario,G36,G37,G38) | H39: =CHOOSE(Scenario,H36,H37,H38) | I39: =CHOOSE(Scenario,I36,I37,I38)
A41: Price growth adjustment (added each plan year)
A42: Base | B42: 0
A43: Downside | B43: -0.01
A44: Upside | B44: 0.005
A45: Active, by year | D45: 0 | E45: =CHOOSE(Scenario,$B$42,$B$43,$B$44) | F45: =CHOOSE(Scenario,$B$42,$B$43,$B$44) | G45: =CHOOSE(Scenario,$B$42,$B$43,$B$44) | H45: =CHOOSE(Scenario,$B$42,$B$43,$B$44) | I45: =CHOOSE(Scenario,$B$42,$B$43,$B$44)

Sheet Macro
A1: Macro backdrop: US construction demand (source: FRED, Federal Reserve Bank of St. Louis)
A2: Annual averages of monthly (weekly for mortgage rate) data; FY2026 = year to date.
A4: Series | B4: FRED ID | C4: 2019 | D4: 2020 | E4: 2021 | F4: 2022 | G4: 2023 | H4: 2024 | I4: 2025 | J4: 2026 | K4: 2026 YTD vs. 2025 YTD | L4: Latest value | M4: Latest date
A5: Housing starts (thousand units, SAAR) | B5: HOUST | C5: 1291.5 | D5: 1394.33 | E5: 1603.33 | F5: 1550.25 | G5: 1420.92 | H5: 1370 | I5: 1355.83 | J5: 1351.78 | K5: -0.0109 | L5: 1221 | M5: 2026-09-01
A6: Total construction spending ($M, SAAR) | B6: TTLCONS | C6: 1390031.7 | D6: 1500455.7 | E6: 1653987.3 | F6: 1900433.8 | G6: 2073357.2 | H6: 2237804.3 | I6: 2244779.7 | J6: 2187037.2 | K6: -0.0287 | L6: 2203129 | M6: 2026-08-01
A7: Highway & street construction spending ($M, SAAR) | B7: TLHWYCONS | C7: 99261.17 | D7: 102884.92 | E7: 103449.33 | F7: 114886.25 | G7: 138874.25 | H7: 148669.17 | I7: 147419 | J7: 151150.25 | K7: 0.0208 | L7: 152213 | M7: 2026-08-01
A8: 30-year fixed mortgage rate (%) | B8: MORTGAGE30US | C8: 3.94 | D8: 3.11 | E8: 2.96 | F8: 5.34 | G8: 6.81 | H8: 6.72 | I8: 6.6 | J8: 6.5 | K8: -0.0263 | L8: 7.32 | M8: 2026-10-22
A9: PPI: construction materials (index 1982=100) | B9: WPUSI012011 | C9: 235.73 | D9: 239.18 | E9: 303.41 | F9: 341.53 | G9: 331.78 | H9: 328.52 | I9: 337.91 | J9: 364.24 | K9: 0.0814 | L9: 378.61 | M9: 2026-09-01
A12: Volume driver growth used in the plan
A13: FY2026 links to the actual year-to-date change above; FY2027-FY2031 are planning assumptions.
C14: 2025 | D14: 2026 | E14: 2027 | F14: 2028 | G14: 2029 | H14: 2030 | I14: 2031
A15: Driver | C15: FY2025A | D15: FY2026F (9+3) | E15: FY2027 Budget | F15: FY2028 Plan | G15: FY2029 Plan | H15: FY2030 Plan | I15: FY2031 Plan
A16: Housing starts (thousand units, SAAR) | B16: HOUST | D16: =$K$5 | E16: 0.01 | F16: 0.03 | G16: 0.03 | H16: 0.02 | I16: 0.02
A17: Total construction spending ($M, SAAR) | B17: TTLCONS | D17: =$K$6 | E17: 0 | F17: 0.02 | G17: 0.03 | H17: 0.03 | I17: 0.03
A18: Highway & street construction spending ($M, SAAR) | B18: TLHWYCONS | D18: =$K$7 | E18: 0.03 | F18: 0.03 | G18: 0.02 | H18: 0.02 | I18: 0.02

Sheet Projects
A1: Growth CAPEX project register
A2: Spend schedule = latest forecast by year. Variance: + = under budget. Returns use after-tax EBITDA uplift from the in-service year, 20-year horizon.
A4: ID | B4: Operating company | C4: Project | D4: Type | E4: Approved budget | F4: Spend FY2026 | G4: Spend FY2027 | H4: Spend FY2028 | I4: Spend FY2029 | J4: Spend FY2030 | K4: Spend FY2031 | L4: Forecast total | M4: Over/(under) approved | N4: FY2026 budget | O4: FY2026 YTD Sep | P4: FY2026 forecast | Q4: FY2026 variance | R4: In-service year | S4: Annual EBITDA uplift | T4: NPV @ WACC | U4: IRR | V4: Payback (years) | W4: Status
A5: G1 | B5: Aggregates | C5: Southeast greenfield quarry | D5: Growth | E5: 160 | F5: 31 | G5: 94 | H5: 35 | I5: 0 | J5: 0 | K5: 0 | L5: =SUM(F5:K5) | M5: =L5-E5 | N5: 40 | O5: 19.8 | P5: =F5 | Q5: =N5-P5 | R5: 2029 | S5: 32 | T5: =C18+NPV(WACC,D18:V18) | U5: =IRR(C18:V18) | V5: =COUNTIF(C29:V29,"<0") | W5: Delayed: permitting; $9M shifted to 2027
A6: G2 | B6: Aggregates | C6: Rail-served distribution yard | D6: Growth | E6: 40 | F6: 18 | G6: 22 | H6: 0 | I6: 0 | J6: 0 | K6: 0 | L6: =SUM(F6:K6) | M6: =L6-E6 | N6: 18 | O6: 13.1 | P6: =F6 | Q6: =N6-P6 | R6: 2028 | S6: 9 | T6: =C19+NPV(WACC,D19:V19) | U6: =IRR(C19:V19) | V6: =COUNTIF(C30:V30,"<0") | W6: On track
A7: G3 | B7: Cement | C7: Kiln efficiency and alternative fuels | D7: Growth | E7: 75 | F7: 36 | G7: 45 | H7: 0 | I7: 0 | J7: 0 | K7: 0 | L7: =SUM(F7:K7) | M7: =L7-E7 | N7: 30 | O7: 27.4 | P7: =F7 | Q7: =N7-P7 | R7: 2028 | S7: 14 | T7: =C20+NPV(WACC,D20:V20) | U7: =IRR(C20:V20) | V7: =COUNTIF(C31:V31,"<0") | W7: Over budget: equipment cost +$6M
A8: G4 | B8: Cement | C8: Import terminal expansion | D8: Growth | E8: 55 | F8: 0 | G8: 25 | H8: 30 | I8: 0 | J8: 0 | K8: 0 | L8: =SUM(F8:K8) | M8: =L8-E8 | N8: 0 | O8: 0 | P8: =F8 | Q8: =N8-P8 | R8: 2029 | S8: 8 | T8: =C21+NPV(WACC,D21:V21) | U8: =IRR(C21:V21) | V8: =COUNTIF(C32:V32,"<0") | W8: Approved; starts 2027
A9: G5 | B9: Ready-Mix Concrete | C9: Plant automation (8 plants) | D9: Growth | E9: 26 | F9: 12 | G9: 14 | H9: 0 | I9: 0 | J9: 0 | K9: 0 | L9: =SUM(F9:K9) | M9: =L9-E9 | N9: 12 | O9: 8.6 | P9: =F9 | Q9: =N9-P9 | R9: 2028 | S9: 6 | T9: =C22+NPV(WACC,D22:V22) | U9: =IRR(C22:V22) | V9: =COUNTIF(C33:V33,"<0") | W9: On track
A10: G6 | B10: Ready-Mix Concrete | C10: Two new Texas plants | D10: Growth | E10: 46 | F10: 0 | G10: 20 | H10: 26 | I10: 0 | J10: 0 | K10: 0 | L10: =SUM(F10:K10) | M10: =L10-E10 | N10: 0 | O10: 0 | P10: =F10 | Q10: =N10-P10 | R10: 2029 | S10: 7 | T10: =C23+NPV(WACC,D23:V23) | U10: =IRR(C23:V23) | V10: =COUNTIF(C34:V34,"<0") | W10: Approved; starts 2027
A11: G7 | B11: Asphalt & Paving | C11: Recycled asphalt (RAP) upgrade | D11: Growth | E11: 22 | F11: 7 | G11: 15 | H11: 0 | I11: 0 | J11: 0 | K11: 0 | L11: =SUM(F11:K11) | M11: =L11-E11 | N11: 10 | O11: 4.2 | P11: =F11 | Q11: =N11-P11 | R11: 2028 | S11: 5 | T11: =C24+NPV(WACC,D24:V24) | U11: =IRR(C24:V24) | V11: =COUNTIF(C35:V35,"<0") | W11: Delayed: vendor lead time; $3M shifted to 2027
A12: G8 | B12: Asphalt & Paving | C12: Hot-mix plant bolt-on acquisition | D12: Growth | E12: 45 | F12: 0 | G12: 0 | H12: 45 | I12: 0 | J12: 0 | K12: 0 | L12: =SUM(F12:K12) | M12: =L12-E12 | N12: 0 | O12: 0 | P12: =F12 | Q12: =N12-P12 | R12: 2029 | S12: 9.5 | T12: =C25+NPV(WACC,D25:V25) | U12: =IRR(C25:V25) | V12: =COUNTIF(C36:V36,"<0") | W12: Pipeline; board approval 2027
C13: Total | E13: =SUM(E5:E12) | F13: =SUM(F5:F12) | G13: =SUM(G5:G12) | H13: =SUM(H5:H12) | I13: =SUM(I5:I12) | J13: =SUM(J5:J12) | K13: =SUM(K5:K12) | L13: =SUM(L5:L12) | ... Q13: =SUM(Q5:Q12) | S13: =SUM(S5:S12) | T13: =SUM(T5:T12)
A16: Project cash flows: -spend + EBITDA uplift x (1 - tax) once in service
A17: ID | B17: Project | C17: 2026 | D17: 2027 | E17: 2028 | F17: 2029 | G17: 2030 | H17: 2031 | I17: 2032 | J17: 2033 | K17: 2034 | L17: 2035 | M17: 2036 | N17: 2037 | O17: 2038 | P17: 2039 | Q17: 2040 | R17: 2041 | S17: 2042 | T17: 2043 | U17: 2044 | V17: 2045
A18: =A5 | B18: =C5 | C18: =-F5+IF(2026>=$R$5,$S$5*(1-TaxRate),0) | D18: =-G5+IF(2027>=$R$5,$S$5*(1-TaxRate),0) | E18: =-H5+IF(2028>=$R$5,$S$5*(1-TaxRate),0) | F18: =-I5+IF(2029>=$R$5,$S$5*(1-TaxRate),0) | G18: =-J5+IF(2030>=$R$5,$S$5*(1-TaxRate),0) | H18: =-K5+IF(2031>=$R$5,$S$5*(1-TaxRate),0) | I18: =0+IF(2032>=$R$5,$S$5*(1-TaxRate),0) | J18: =0+IF(2033>=$R$5,$S$5*(1-TaxRate),0) | K18: =0+IF(2034>=$R$5,$S$5*(1-TaxRate),0) | L18: =0+IF(2035>=$R$5,$S$5*(1-TaxRate),0) | M18: =0+IF(2036>=$R$5,$S$5*(1-TaxRate),0) | N18: =0+IF(2037>=$R$5,$S$5*(1-TaxRate),0) | O18: =0+IF(2038>=$R$5,$S$5*(1-TaxRate),0) | P18: =0+IF(2039>=$R$5,$S$5*(1-TaxRate),0) | Q18: =0+IF(2040>=$R$5,$S$5*(1-TaxRate),0) | R18: =0+IF(2041>=$R$5,$S$5*(1-TaxRate),0) | S18: =0+IF(2042>=$R$5,$S$5*(1-TaxRate),0) | T18: =0+IF(2043>=$R$5,$S$5*(1-TaxRate),0) | U18: =0+IF(2044>=$R$5,$S$5*(1-TaxRate),0) | V18: =0+IF(2045>=$R$5,$S$5*(1-TaxRate),0)
A19: =A6 | B19: =C6 | C19: =-F6+IF(2026>=$R$6,$S$6*(1-TaxRate),0) | D19: =-G6+IF(2027>=$R$6,$S$6*(1-TaxRate),0) | E19: =-H6+IF(2028>=$R$6,$S$6*(1-TaxRate),0) | F19: =-I6+IF(2029>=$R$6,$S$6*(1-TaxRate),0) | G19: =-J6+IF(2030>=$R$6,$S$6*(1-TaxRate),0) | H19: =-K6+IF(2031>=$R$6,$S$6*(1-TaxRate),0) | I19: =0+IF(2032>=$R$6,$S$6*(1-TaxRate),0) | J19: =0+IF(2033>=$R$6,$S$6*(1-TaxRate),0) | K19: =0+IF(2034>=$R$6,$S$6*(1-TaxRate),0) | L19: =0+IF(2035>=$R$6,$S$6*(1-TaxRate),0) | M19: =0+IF(2036>=$R$6,$S$6*(1-TaxRate),0) | N19: =0+IF(2037>=$R$6,$S$6*(1-TaxRate),0) | O19: =0+IF(2038>=$R$6,$S$6*(1-TaxRate),0) | P19: =0+IF(2039>=$R$6,$S$6*(1-TaxRate),0) | Q19: =0+IF(2040>=$R$6,$S$6*(1-TaxRate),0) | R19: =0+IF(2041>=$R$6,$S$6*(1-TaxRate),0) | S19: =0+IF(2042>=$R$6,$S$6*(1-TaxRate),0) | T19: =0+IF(2043>=$R$6,$S$6*(1-TaxRate),0) | U19: =0+IF(2044>=$R$6,$S$6*(1-TaxRate),0) | V19: =0+IF(2045>=$R$6,$S$6*(1-TaxRate),0)
A20: =A7 | B20: =C7 | C20: =-F7+IF(2026>=$R$7,$S$7*(1-TaxRate),0) | D20: =-G7+IF(2027>=$R$7,$S$7*(1-TaxRate),0) | E20: =-H7+IF(2028>=$R$7,$S$7*(1-TaxRate),0) | F20: =-I7+IF(2029>=$R$7,$S$7*(1-TaxRate),0) | G20: =-J7+IF(2030>=$R$7,$S$7*(1-TaxRate),0) | H20: =-K7+IF(2031>=$R$7,$S$7*(1-TaxRate),0) | I20: =0+IF(2032>=$R$7,$S$7*(1-TaxRate),0) | J20: =0+IF(2033>=$R$7,$S$7*(1-TaxRate),0) | K20: =0+IF(2034>=$R$7,$S$7*(1-TaxRate),0) | L20: =0+IF(2035>=$R$7,$S$7*(1-TaxRate),0) | M20: =0+IF(2036>=$R$7,$S$7*(1-TaxRate),0) | N20: =0+IF(2037>=$R$7,$S$7*(1-TaxRate),0) | O20: =0+IF(2038>=$R$7,$S$7*(1-TaxRate),0) | P20: =0+IF(2039>=$R$7,$S$7*(1-TaxRate),0) | Q20: =0+IF(2040>=$R$7,$S$7*(1-TaxRate),0) | R20: =0+IF(2041>=$R$7,$S$7*(1-TaxRate),0) | S20: =0+IF(2042>=$R$7,$S$7*(1-TaxRate),0) | T20: =0+IF(2043>=$R$7,$S$7*(1-TaxRate),0) | U20: =0+IF(2044>=$R$7,$S$7*(1-TaxRate),0) | V20: =0+IF(2045>=$R$7,$S$7*(1-TaxRate),0)
A21: =A8 | B21: =C8 | C21: =-F8+IF(2026>=$R$8,$S$8*(1-TaxRate),0) | D21: =-G8+IF(2027>=$R$8,$S$8*(1-TaxRate),0) | E21: =-H8+IF(2028>=$R$8,$S$8*(1-TaxRate),0) | F21: =-I8+IF(2029>=$R$8,$S$8*(1-TaxRate),0) | G21: =-J8+IF(2030>=$R$8,$S$8*(1-TaxRate),0) | H21: =-K8+IF(2031>=$R$8,$S$8*(1-TaxRate),0) | I21: =0+IF(2032>=$R$8,$S$8*(1-TaxRate),0) | J21: =0+IF(2033>=$R$8,$S$8*(1-TaxRate),0) | K21: =0+IF(2034>=$R$8,$S$8*(1-TaxRate),0) | L21: =0+IF(2035>=$R$8,$S$8*(1-TaxRate),0) | M21: =0+IF(2036>=$R$8,$S$8*(1-TaxRate),0) | N21: =0+IF(2037>=$R$8,$S$8*(1-TaxRate),0) | O21: =0+IF(2038>=$R$8,$S$8*(1-TaxRate),0) | P21: =0+IF(2039>=$R$8,$S$8*(1-TaxRate),0) | Q21: =0+IF(2040>=$R$8,$S$8*(1-TaxRate),0) | R21: =0+IF(2041>=$R$8,$S$8*(1-TaxRate),0) | S21: =0+IF(2042>=$R$8,$S$8*(1-TaxRate),0) | T21: =0+IF(2043>=$R$8,$S$8*(1-TaxRate),0) | U21: =0+IF(2044>=$R$8,$S$8*(1-TaxRate),0) | V21: =0+IF(2045>=$R$8,$S$8*(1-TaxRate),0)
A22: =A9 | B22: =C9 | C22: =-F9+IF(2026>=$R$9,$S$9*(1-TaxRate),0) | D22: =-G9+IF(2027>=$R$9,$S$9*(1-TaxRate),0) | E22: =-H9+IF(2028>=$R$9,$S$9*(1-TaxRate),0) | F22: =-I9+IF(2029>=$R$9,$S$9*(1-TaxRate),0) | G22: =-J9+IF(2030>=$R$9,$S$9*(1-TaxRate),0) | H22: =-K9+IF(2031>=$R$9,$S$9*(1-TaxRate),0) | I22: =0+IF(2032>=$R$9,$S$9*(1-TaxRate),0) | J22: =0+IF(2033>=$R$9,$S$9*(1-TaxRate),0) | K22: =0+IF(2034>=$R$9,$S$9*(1-TaxRate),0) | L22: =0+IF(2035>=$R$9,$S$9*(1-TaxRate),0) | M22: =0+IF(2036>=$R$9,$S$9*(1-TaxRate),0) | N22: =0+IF(2037>=$R$9,$S$9*(1-TaxRate),0) | O22: =0+IF(2038>=$R$9,$S$9*(1-TaxRate),0) | P22: =0+IF(2039>=$R$9,$S$9*(1-TaxRate),0) | Q22: =0+IF(2040>=$R$9,$S$9*(1-TaxRate),0) | R22: =0+IF(2041>=$R$9,$S$9*(1-TaxRate),0) | S22: =0+IF(2042>=$R$9,$S$9*(1-TaxRate),0) | T22: =0+IF(2043>=$R$9,$S$9*(1-TaxRate),0) | U22: =0+IF(2044>=$R$9,$S$9*(1-TaxRate),0) | V22: =0+IF(2045>=$R$9,$S$9*(1-TaxRate),0)
A23: =A10 | B23: =C10 | C23: =-F10+IF(2026>=$R$10,$S$10*(1-TaxRate),0) | D23: =-G10+IF(2027>=$R$10,$S$10*(1-TaxRate),0) | E23: =-H10+IF(2028>=$R$10,$S$10*(1-TaxRate),0) | F23: =-I10+IF(2029>=$R$10,$S$10*(1-TaxRate),0) | G23: =-J10+IF(2030>=$R$10,$S$10*(1-TaxRate),0) | H23: =-K10+IF(2031>=$R$10,$S$10*(1-TaxRate),0) | I23: =0+IF(2032>=$R$10,$S$10*(1-TaxRate),0) | J23: =0+IF(2033>=$R$10,$S$10*(1-TaxRate),0) | K23: =0+IF(2034>=$R$10,$S$10*(1-TaxRate),0) | L23: =0+IF(2035>=$R$10,$S$10*(1-TaxRate),0) | M23: =0+IF(2036>=$R$10,$S$10*(1-TaxRate),0) | N23: =0+IF(2037>=$R$10,$S$10*(1-TaxRate),0) | O23: =0+IF(2038>=$R$10,$S$10*(1-TaxRate),0) | P23: =0+IF(2039>=$R$10,$S$10*(1-TaxRate),0) | Q23: =0+IF(2040>=$R$10,$S$10*(1-TaxRate),0) | R23: =0+IF(2041>=$R$10,$S$10*(1-TaxRate),0) | S23: =0+IF(2042>=$R$10,$S$10*(1-TaxRate),0) | T23: =0+IF(2043>=$R$10,$S$10*(1-TaxRate),0) | U23: =0+IF(2044>=$R$10,$S$10*(1-TaxRate),0) | V23: =0+IF(2045>=$R$10,$S$10*(1-TaxRate),0)
A24: =A11 | B24: =C11 | C24: =-F11+IF(2026>=$R$11,$S$11*(1-TaxRate),0) | D24: =-G11+IF(2027>=$R$11,$S$11*(1-TaxRate),0) | E24: =-H11+IF(2028>=$R$11,$S$11*(1-TaxRate),0) | F24: =-I11+IF(2029>=$R$11,$S$11*(1-TaxRate),0) | G24: =-J11+IF(2030>=$R$11,$S$11*(1-TaxRate),0) | H24: =-K11+IF(2031>=$R$11,$S$11*(1-TaxRate),0) | I24: =0+IF(2032>=$R$11,$S$11*(1-TaxRate),0) | J24: =0+IF(2033>=$R$11,$S$11*(1-TaxRate),0) | K24: =0+IF(2034>=$R$11,$S$11*(1-TaxRate),0) | L24: =0+IF(2035>=$R$11,$S$11*(1-TaxRate),0) | M24: =0+IF(2036>=$R$11,$S$11*(1-TaxRate),0) | N24: =0+IF(2037>=$R$11,$S$11*(1-TaxRate),0) | O24: =0+IF(2038>=$R$11,$S$11*(1-TaxRate),0) | P24: =0+IF(2039>=$R$11,$S$11*(1-TaxRate),0) | Q24: =0+IF(2040>=$R$11,$S$11*(1-TaxRate),0) | R24: =0+IF(2041>=$R$11,$S$11*(1-TaxRate),0) | S24: =0+IF(2042>=$R$11,$S$11*(1-TaxRate),0) | T24: =0+IF(2043>=$R$11,$S$11*(1-TaxRate),0) | U24: =0+IF(2044>=$R$11,$S$11*(1-TaxRate),0) | V24: =0+IF(2045>=$R$11,$S$11*(1-TaxRate),0)
A25: =A12 | B25: =C12 | C25: =-F12+IF(2026>=$R$12,$S$12*(1-TaxRate),0) | D25: =-G12+IF(2027>=$R$12,$S$12*(1-TaxRate),0) | E25: =-H12+IF(2028>=$R$12,$S$12*(1-TaxRate),0) | F25: =-I12+IF(2029>=$R$12,$S$12*(1-TaxRate),0) | G25: =-J12+IF(2030>=$R$12,$S$12*(1-TaxRate),0) | H25: =-K12+IF(2031>=$R$12,$S$12*(1-TaxRate),0) | I25: =0+IF(2032>=$R$12,$S$12*(1-TaxRate),0) | J25: =0+IF(2033>=$R$12,$S$12*(1-TaxRate),0) | K25: =0+IF(2034>=$R$12,$S$12*(1-TaxRate),0) | L25: =0+IF(2035>=$R$12,$S$12*(1-TaxRate),0) | M25: =0+IF(2036>=$R$12,$S$12*(1-TaxRate),0) | N25: =0+IF(2037>=$R$12,$S$12*(1-TaxRate),0) | O25: =0+IF(2038>=$R$12,$S$12*(1-TaxRate),0) | P25: =0+IF(2039>=$R$12,$S$12*(1-TaxRate),0) | Q25: =0+IF(2040>=$R$12,$S$12*(1-TaxRate),0) | R25: =0+IF(2041>=$R$12,$S$12*(1-TaxRate),0) | S25: =0+IF(2042>=$R$12,$S$12*(1-TaxRate),0) | T25: =0+IF(2043>=$R$12,$S$12*(1-TaxRate),0) | U25: =0+IF(2044>=$R$12,$S$12*(1-TaxRate),0) | V25: =0+IF(2045>=$R$12,$S$12*(1-TaxRate),0)
A28: ID | B28: Cumulative | C28: 2026 | D28: 2027 | E28: 2028 | F28: 2029 | G28: 2030 | H28: 2031 | I28: 2032 | J28: 2033 | K28: 2034 | L28: 2035 | M28: 2036 | N28: 2037 | O28: 2038 | P28: 2039 | Q28: 2040 | R28: 2041 | S28: 2042 | T28: 2043 | U28: 2044 | V28: 2045
A29: =A5 | C29: =C18 | D29: =C29+D18 | E29: =D29+E18 | F29: =E29+F18 | G29: =F29+G18 | H29: =G29+H18 | I29: =H29+I18 | J29: =I29+J18 | K29: =J29+K18 | ... V29: =U29+V18
A30: =A6 | C30: =C19 | D30: =C30+D19 | E30: =D30+E19 | F30: =E30+F19 | G30: =F30+G19 | H30: =G30+H19 | I30: =H30+I19 | J30: =I30+J19 | K30: =J30+K19 | ... V30: =U30+V19
A31: =A7 | C31: =C20 | D31: =C31+D20 | E31: =D31+E20 | F31: =E31+F20 | G31: =F31+G20 | H31: =G31+H20 | I31: =H31+I20 | J31: =I31+J20 | K31: =J31+K20 | ... V31: =U31+V20
A32: =A8 | C32: =C21 | D32: =C32+D21 | E32: =D32+E21 | F32: =E32+F21 | G32: =F32+G21 | H32: =G32+H21 | I32: =H32+I21 | J32: =I32+J21 | K32: =J32+K21 | ... V32: =U32+V21
A33: =A9 | C33: =C22 | D33: =C33+D22 | E33: =D33+E22 | F33: =E33+F22 | G33: =F33+G22 | H33: =G33+H22 | I33: =H33+I22 | J33: =I33+J22 | K33: =J33+K22 | ... V33: =U33+V22
A34: =A10 | C34: =C23 | D34: =C34+D23 | E34: =D34+E23 | F34: =E34+F23 | G34: =F34+G23 | H34: =G34+H23 | I34: =H34+I23 | J34: =I34+J23 | K34: =J34+K23 | ... V34: =U34+V23
A35: =A11 | C35: =C24 | D35: =C35+D24 | E35: =D35+E24 | F35: =E35+F24 | G35: =F35+G24 | H35: =G35+H24 | I35: =H35+I24 | J35: =I35+J24 | K35: =J35+K24 | ... V35: =U35+V24
A36: =A12 | C36: =C25 | D36: =C36+D25 | E36: =D36+E25 | F36: =E36+F25 | G36: =F36+G25 | H36: =G36+H25 | I36: =H36+I25 | J36: =I36+J25 | K36: =J36+K25 | ... V36: =U36+V25

Sheet OpCo_Plan
A1: Operating company plans: volume x price build
C2: 2025 | D2: 2026 | E2: 2027 | F2: 2028 | G2: 2029 | H2: 2030 | I2: 2031
A3: $ millions | C3: FY2025A | D3: FY2026F (9+3) | E3: FY2027 Budget | F3: FY2028 Plan | G3: FY2029 Plan | H3: FY2030 Plan | I3: FY2031 Plan
A4: Aggregates (driver: TLHWYCONS, volume in million tons)
A5: Macro driver growth | D5: =Macro!D$18 | E5: =Macro!E$18 | F5: =Macro!F$18 | G5: =Macro!G$18 | H5: =Macro!H$18 | I5: =Macro!I$18
A6: Volume growth | D6: =Inputs!$E$20+Inputs!$D$20*D5+Inputs!D$39 | E6: =Inputs!$E$20+Inputs!$D$20*E5+Inputs!E$39 | F6: =Inputs!$E$20+Inputs!$D$20*F5+Inputs!F$39 | G6: =Inputs!$E$20+Inputs!$D$20*G5+Inputs!G$39 | H6: =Inputs!$E$20+Inputs!$D$20*H5+Inputs!H$39 | I6: =Inputs!$E$20+Inputs!$D$20*I5+Inputs!I$39
A7: Volume (M units) | C7: =Inputs!$F$20 | D7: =C7*(1+D6) | E7: =D7*(1+E6) | F7: =E7*(1+F6) | G7: =F7*(1+G6) | H7: =G7*(1+H6) | I7: =H7*(1+I6)
A8: Price growth | D8: =Inputs!D$28+Inputs!D$45 | E8: =Inputs!E$28+Inputs!E$45 | F8: =Inputs!F$28+Inputs!F$45 | G8: =Inputs!G$28+Inputs!G$45 | H8: =Inputs!H$28+Inputs!H$45 | I8: =Inputs!I$28+Inputs!I$45
A9: Price per unit ($) | C9: =Inputs!$G$20 | D9: =C9*(1+D8) | E9: =D9*(1+E8) | F9: =E9*(1+F8) | G9: =F9*(1+G8) | H9: =G9*(1+H8) | I9: =H9*(1+I8)
A10: Revenue | C10: =C7*C9 | D10: =D7*D9 | E10: =E7*E9 | F10: =F7*F9 | G10: =G7*G9 | H10: =H7*H9 | I10: =I7*I9
A11: Variable cost per unit ($) | C11: =Inputs!$H$20 | D11: =C11*(1+Inputs!$J$20) | E11: =D11*(1+Inputs!$J$20) | F11: =E11*(1+Inputs!$J$20) | G11: =F11*(1+Inputs!$J$20) | H11: =G11*(1+Inputs!$J$20) | I11: =H11*(1+Inputs!$J$20)
A12: Variable costs | C12: =C7*C11 | D12: =D7*D11 | E12: =E7*E11 | F12: =F7*F11 | G12: =G7*G11 | H12: =H7*H11 | I12: =I7*I11
A13: Fixed costs | C13: =Inputs!$I$20 | D13: =C13*(1+Inputs!$K$20) | E13: =D13*(1+Inputs!$K$20) | F13: =E13*(1+Inputs!$K$20) | G13: =F13*(1+Inputs!$K$20) | H13: =G13*(1+Inputs!$K$20) | I13: =H13*(1+Inputs!$K$20)
A14: Growth project EBITDA | C14: =SUMIFS(Projects!$S$5:$S$12,Projects!$B$5:$B$12,"Aggregates",Projects!$R$5:$R$12,"<="&C$2) | D14: =SUMIFS(Projects!$S$5:$S$12,Projects!$B$5:$B$12,"Aggregates",Projects!$R$5:$R$12,"<="&D$2) | E14: =SUMIFS(Projects!$S$5:$S$12,Projects!$B$5:$B$12,"Aggregates",Projects!$R$5:$R$12,"<="&E$2) | F14: =SUMIFS(Projects!$S$5:$S$12,Projects!$B$5:$B$12,"Aggregates",Projects!$R$5:$R$12,"<="&F$2) | G14: =SUMIFS(Projects!$S$5:$S$12,Projects!$B$5:$B$12,"Aggregates",Projects!$R$5:$R$12,"<="&G$2) | H14: =SUMIFS(Projects!$S$5:$S$12,Projects!$B$5:$B$12,"Aggregates",Projects!$R$5:$R$12,"<="&H$2) | I14: =SUMIFS(Projects!$S$5:$S$12,Projects!$B$5:$B$12,"Aggregates",Projects!$R$5:$R$12,"<="&I$2)
A15: EBITDA | C15: =C10-C12-C13+C14 | D15: =D10-D12-D13+D14 | E15: =E10-E12-E13+E14 | F15: =F10-F12-F13+F14 | G15: =G10-G12-G13+G14 | H15: =H10-H12-H13+H14 | I15: =I10-I12-I13+I14
A16: EBITDA margin | C16: =C15/C10 | D16: =D15/D10 | E16: =E15/E10 | F16: =F15/F10 | G16: =G15/G10 | H16: =H15/H10 | I16: =I15/I10
A17: Maintenance capex | D17: =Inputs!$L$20*D10 | E17: =Inputs!$L$20*E10 | F17: =Inputs!$L$20*F10 | G17: =Inputs!$L$20*G10 | H17: =Inputs!$L$20*H10 | I17: =Inputs!$L$20*I10
A18: Growth capex | D18: =SUMIF(Projects!$B$5:$B$12,"Aggregates",Projects!$F$5:$F$12) | E18: =SUMIF(Projects!$B$5:$B$12,"Aggregates",Projects!$G$5:$G$12) | F18: =SUMIF(Projects!$B$5:$B$12,"Aggregates",Projects!$H$5:$H$12) | G18: =SUMIF(Projects!$B$5:$B$12,"Aggregates",Projects!$I$5:$I$12) | H18: =SUMIF(Projects!$B$5:$B$12,"Aggregates",Projects!$J$5:$J$12) | I18: =SUMIF(Projects!$B$5:$B$12,"Aggregates",Projects!$K$5:$K$12)
A19: Total capex | C19: =Inputs!$M$20 | D19: =D17+D18 | E19: =E17+E18 | F19: =F17+F18 | G19: =G17+G18 | H19: =H17+H18 | I19: =I17+I18
A21: Cement (driver: TTLCONS, volume in million tons)
A22: Macro driver growth | D22: =Macro!D$17 | E22: =Macro!E$17 | F22: =Macro!F$17 | G22: =Macro!G$17 | H22: =Macro!H$17 | I22: =Macro!I$17
A23: Volume growth | D23: =Inputs!$E$21+Inputs!$D$21*D22+Inputs!D$39 | E23: =Inputs!$E$21+Inputs!$D$21*E22+Inputs!E$39 | F23: =Inputs!$E$21+Inputs!$D$21*F22+Inputs!F$39 | G23: =Inputs!$E$21+Inputs!$D$21*G22+Inputs!G$39 | H23: =Inputs!$E$21+Inputs!$D$21*H22+Inputs!H$39 | I23: =Inputs!$E$21+Inputs!$D$21*I22+Inputs!I$39
A24: Volume (M units) | C24: =Inputs!$F$21 | D24: =C24*(1+D23) | E24: =D24*(1+E23) | F24: =E24*(1+F23) | G24: =F24*(1+G23) | H24: =G24*(1+H23) | I24: =H24*(1+I23)
A25: Price growth | D25: =Inputs!D$29+Inputs!D$45 | E25: =Inputs!E$29+Inputs!E$45 | F25: =Inputs!F$29+Inputs!F$45 | G25: =Inputs!G$29+Inputs!G$45 | H25: =Inputs!H$29+Inputs!H$45 | I25: =Inputs!I$29+Inputs!I$45
A26: Price per unit ($) | C26: =Inputs!$G$21 | D26: =C26*(1+D25) | E26: =D26*(1+E25) | F26: =E26*(1+F25) | G26: =F26*(1+G25) | H26: =G26*(1+H25) | I26: =H26*(1+I25)
A27: Revenue | C27: =C24*C26 | D27: =D24*D26 | E27: =E24*E26 | F27: =F24*F26 | G27: =G24*G26 | H27: =H24*H26 | I27: =I24*I26
A28: Variable cost per unit ($) | C28: =Inputs!$H$21 | D28: =C28*(1+Inputs!$J$21) | E28: =D28*(1+Inputs!$J$21) | F28: =E28*(1+Inputs!$J$21) | G28: =F28*(1+Inputs!$J$21) | H28: =G28*(1+Inputs!$J$21) | I28: =H28*(1+Inputs!$J$21)
A29: Variable costs | C29: =C24*C28 | D29: =D24*D28 | E29: =E24*E28 | F29: =F24*F28 | G29: =G24*G28 | H29: =H24*H28 | I29: =I24*I28
A30: Fixed costs | C30: =Inputs!$I$21 | D30: =C30*(1+Inputs!$K$21) | E30: =D30*(1+Inputs!$K$21) | F30: =E30*(1+Inputs!$K$21) | G30: =F30*(1+Inputs!$K$21) | H30: =G30*(1+Inputs!$K$21) | I30: =H30*(1+Inputs!$K$21)
A31: Growth project EBITDA | C31: =SUMIFS(Projects!$S$5:$S$12,Projects!$B$5:$B$12,"Cement",Projects!$R$5:$R$12,"<="&C$2) | D31: =SUMIFS(Projects!$S$5:$S$12,Projects!$B$5:$B$12,"Cement",Projects!$R$5:$R$12,"<="&D$2) | E31: =SUMIFS(Projects!$S$5:$S$12,Projects!$B$5:$B$12,"Cement",Projects!$R$5:$R$12,"<="&E$2) | F31: =SUMIFS(Projects!$S$5:$S$12,Projects!$B$5:$B$12,"Cement",Projects!$R$5:$R$12,"<="&F$2) | G31: =SUMIFS(Projects!$S$5:$S$12,Projects!$B$5:$B$12,"Cement",Projects!$R$5:$R$12,"<="&G$2) | H31: =SUMIFS(Projects!$S$5:$S$12,Projects!$B$5:$B$12,"Cement",Projects!$R$5:$R$12,"<="&H$2) | I31: =SUMIFS(Projects!$S$5:$S$12,Projects!$B$5:$B$12,"Cement",Projects!$R$5:$R$12,"<="&I$2)
A32: EBITDA | C32: =C27-C29-C30+C31 | D32: =D27-D29-D30+D31 | E32: =E27-E29-E30+E31 | F32: =F27-F29-F30+F31 | G32: =G27-G29-G30+G31 | H32: =H27-H29-H30+H31 | I32: =I27-I29-I30+I31
A33: EBITDA margin | C33: =C32/C27 | D33: =D32/D27 | E33: =E32/E27 | F33: =F32/F27 | G33: =G32/G27 | H33: =H32/H27 | I33: =I32/I27
A34: Maintenance capex | D34: =Inputs!$L$21*D27 | E34: =Inputs!$L$21*E27 | F34: =Inputs!$L$21*F27 | G34: =Inputs!$L$21*G27 | H34: =Inputs!$L$21*H27 | I34: =Inputs!$L$21*I27
A35: Growth capex | D35: =SUMIF(Projects!$B$5:$B$12,"Cement",Projects!$F$5:$F$12) | E35: =SUMIF(Projects!$B$5:$B$12,"Cement",Projects!$G$5:$G$12) | F35: =SUMIF(Projects!$B$5:$B$12,"Cement",Projects!$H$5:$H$12) | G35: =SUMIF(Projects!$B$5:$B$12,"Cement",Projects!$I$5:$I$12) | H35: =SUMIF(Projects!$B$5:$B$12,"Cement",Projects!$J$5:$J$12) | I35: =SUMIF(Projects!$B$5:$B$12,"Cement",Projects!$K$5:$K$12)
A36: Total capex | C36: =Inputs!$M$21 | D36: =D34+D35 | E36: =E34+E35 | F36: =F34+F35 | G36: =G34+G35 | H36: =H34+H35 | I36: =I34+I35
A38: Ready-Mix Concrete (driver: HOUST, volume in million cubic yards)
A39: Macro driver growth | D39: =Macro!D$16 | E39: =Macro!E$16 | F39: =Macro!F$16 | G39: =Macro!G$16 | H39: =Macro!H$16 | I39: =Macro!I$16
A40: Volume growth | D40: =Inputs!$E$22+Inputs!$D$22*D39+Inputs!D$39 | E40: =Inputs!$E$22+Inputs!$D$22*E39+Inputs!E$39 | F40: =Inputs!$E$22+Inputs!$D$22*F39+Inputs!F$39 | G40: =Inputs!$E$22+Inputs!$D$22*G39+Inputs!G$39 | H40: =Inputs!$E$22+Inputs!$D$22*H39+Inputs!H$39 | I40: =Inputs!$E$22+Inputs!$D$22*I39+Inputs!I$39
A41: Volume (M units) | C41: =Inputs!$F$22 | D41: =C41*(1+D40) | E41: =D41*(1+E40) | F41: =E41*(1+F40) | G41: =F41*(1+G40) | H41: =G41*(1+H40) | I41: =H41*(1+I40)
A42: Price growth | D42: =Inputs!D$30+Inputs!D$45 | E42: =Inputs!E$30+Inputs!E$45 | F42: =Inputs!F$30+Inputs!F$45 | G42: =Inputs!G$30+Inputs!G$45 | H42: =Inputs!H$30+Inputs!H$45 | I42: =Inputs!I$30+Inputs!I$45
...

Sheet Consolidation
A1: Granite Peak Materials Group: consolidated plan | C1: ="Scenario: "&Inputs!$C$3
C3: 2025 | D3: 2026 | E3: 2027 | F3: 2028 | G3: 2029 | H3: 2030 | I3: 2031
A4: $ millions | C4: FY2025A | D4: FY2026F (9+3) | E4: FY2027 Budget | F4: FY2028 Plan | G4: FY2029 Plan | H4: FY2030 Plan | I4: FY2031 Plan
A5: Revenue: Aggregates | C5: =OpCo_Plan!C10 | D5: =OpCo_Plan!D10 | E5: =OpCo_Plan!E10 | F5: =OpCo_Plan!F10 | G5: =OpCo_Plan!G10 | H5: =OpCo_Plan!H10 | I5: =OpCo_Plan!I10
A6: Revenue: Cement | C6: =OpCo_Plan!C27 | D6: =OpCo_Plan!D27 | E6: =OpCo_Plan!E27 | F6: =OpCo_Plan!F27 | G6: =OpCo_Plan!G27 | H6: =OpCo_Plan!H27 | I6: =OpCo_Plan!I27
A7: Revenue: Ready-Mix Concrete | C7: =OpCo_Plan!C44 | D7: =OpCo_Plan!D44 | E7: =OpCo_Plan!E44 | F7: =OpCo_Plan!F44 | G7: =OpCo_Plan!G44 | H7: =OpCo_Plan!H44 | I7: =OpCo_Plan!I44
A8: Revenue: Asphalt & Paving | C8: =OpCo_Plan!C61 | D8: =OpCo_Plan!D61 | E8: =OpCo_Plan!E61 | F8: =OpCo_Plan!F61 | G8: =OpCo_Plan!G61 | H8: =OpCo_Plan!H61 | I8: =OpCo_Plan!I61
A9: Total operating company revenue | C9: =SUM(C5:C8) | D9: =SUM(D5:D8) | E9: =SUM(E5:E8) | F9: =SUM(F5:F8) | G9: =SUM(G5:G8) | H9: =SUM(H5:H8) | I9: =SUM(I5:I8)
A10: Intercompany eliminations | C10: =-(C5*Inputs!$N$20+C6*Inputs!$N$21+C7*Inputs!$N$22+C8*Inputs!$N$23) | D10: =-(D5*Inputs!$N$20+D6*Inputs!$N$21+D7*Inputs!$N$22+D8*Inputs!$N$23) | E10: =-(E5*Inputs!$N$20+E6*Inputs!$N$21+E7*Inputs!$N$22+E8*Inputs!$N$23) | F10: =-(F5*Inputs!$N$20+F6*Inputs!$N$21+F7*Inputs!$N$22+F8*Inputs!$N$23) | G10: =-(G5*Inputs!$N$20+G6*Inputs!$N$21+G7*Inputs!$N$22+G8*Inputs!$N$23) | H10: =-(H5*Inputs!$N$20+H6*Inputs!$N$21+H7*Inputs!$N$22+H8*Inputs!$N$23) | I10: =-(I5*Inputs!$N$20+I6*Inputs!$N$21+I7*Inputs!$N$22+I8*Inputs!$N$23)
A11: Consolidated revenue | C11: =C9+C10 | D11: =D9+D10 | E11: =E9+E10 | F11: =F9+F10 | G11: =G9+G10 | H11: =H9+H10 | I11: =I9+I10
A13: EBITDA: Aggregates | C13: =OpCo_Plan!C15 | D13: =OpCo_Plan!D15 | E13: =OpCo_Plan!E15 | F13: =OpCo_Plan!F15 | G13: =OpCo_Plan!G15 | H13: =OpCo_Plan!H15 | I13: =OpCo_Plan!I15
A14: EBITDA: Cement | C14: =OpCo_Plan!C32 | D14: =OpCo_Plan!D32 | E14: =OpCo_Plan!E32 | F14: =OpCo_Plan!F32 | G14: =OpCo_Plan!G32 | H14: =OpCo_Plan!H32 | I14: =OpCo_Plan!I32
A15: EBITDA: Ready-Mix Concrete | C15: =OpCo_Plan!C49 | D15: =OpCo_Plan!D49 | E15: =OpCo_Plan!E49 | F15: =OpCo_Plan!F49 | G15: =OpCo_Plan!G49 | H15: =OpCo_Plan!H49 | I15: =OpCo_Plan!I49
A16: EBITDA: Asphalt & Paving | C16: =OpCo_Plan!C66 | D16: =OpCo_Plan!D66 | E16: =OpCo_Plan!E66 | F16: =OpCo_Plan!F66 | G16: =OpCo_Plan!G66 | H16: =OpCo_Plan!H66 | I16: =OpCo_Plan!I66
A17: Corporate costs | C17: =-CorpCost2025 | D17: =C17*(1+CorpInfl) | E17: =D17*(1+CorpInfl) | F17: =E17*(1+CorpInfl) | G17: =F17*(1+CorpInfl) | H17: =G17*(1+CorpInfl) | I17: =H17*(1+CorpInfl)
A18: Consolidated EBITDA | C18: =SUM(C13:C17) | D18: =SUM(D13:D17) | E18: =SUM(E13:E17) | F18: =SUM(F13:F17) | G18: =SUM(G13:G17) | H18: =SUM(H13:H17) | I18: =SUM(I13:I17)
A19: EBITDA margin | C19: =C18/C11 | D19: =D18/D11 | E19: =E18/E11 | F19: =F18/F11 | G19: =G18/G11 | H19: =H18/H11 | I19: =I18/I11
A20: Intercompany sales are eliminated at cost, so EBITDA is unaffected
A22: Depreciation & amortization | C22: =DA2025 | D22: =C29/AssetLife | E22: =D29/AssetLife | F22: =E29/AssetLife | G22: =F29/AssetLife | H22: =G29/AssetLife | I22: =H29/AssetLife
A23: EBIT | C23: =C18-C22 | D23: =D18-D22 | E23: =E18-E22 | F23: =F18-F22 | G23: =G18-G22 | H23: =H18-H22 | I23: =I18-I22
A24: Cash taxes | D24: =D23*TaxRate | E24: =E23*TaxRate | F24: =F23*TaxRate | G24: =G23*TaxRate | H24: =H23*TaxRate | I24: =I23*TaxRate
A26: Maintenance capex | D26: =OpCo_Plan!D17+OpCo_Plan!D34+OpCo_Plan!D51+OpCo_Plan!D68 | E26: =OpCo_Plan!E17+OpCo_Plan!E34+OpCo_Plan!E51+OpCo_Plan!E68 | F26: =OpCo_Plan!F17+OpCo_Plan!F34+OpCo_Plan!F51+OpCo_Plan!F68 | G26: =OpCo_Plan!G17+OpCo_Plan!G34+OpCo_Plan!G51+OpCo_Plan!G68 | H26: =OpCo_Plan!H17+OpCo_Plan!H34+OpCo_Plan!H51+OpCo_Plan!H68 | I26: =OpCo_Plan!I17+OpCo_Plan!I34+OpCo_Plan!I51+OpCo_Plan!I68
A27: Growth capex | D27: =OpCo_Plan!D18+OpCo_Plan!D35+OpCo_Plan!D52+OpCo_Plan!D69 | E27: =OpCo_Plan!E18+OpCo_Plan!E35+OpCo_Plan!E52+OpCo_Plan!E69 | F27: =OpCo_Plan!F18+OpCo_Plan!F35+OpCo_Plan!F52+OpCo_Plan!F69 | G27: =OpCo_Plan!G18+OpCo_Plan!G35+OpCo_Plan!G52+OpCo_Plan!G69 | H27: =OpCo_Plan!H18+OpCo_Plan!H35+OpCo_Plan!H52+OpCo_Plan!H69 | I27: =OpCo_Plan!I18+OpCo_Plan!I35+OpCo_Plan!I52+OpCo_Plan!I69
A28: Total capex | C28: =OpCo_Plan!C19+OpCo_Plan!C36+OpCo_Plan!C53+OpCo_Plan!C70 | D28: =D26+D27 | E28: =E26+E27 | F28: =F26+F27 | G28: =G26+G27 | H28: =H26+H27 | I28: =I26+I27
A29: Net PP&E (closing) | C29: =PPE2025 | D29: =C29+D28-D22 | E29: =D29+E28-E22 | F29: =E29+F28-F22 | G29: =F29+G28-G22 | H29: =G29+H28-H22 | I29: =H29+I28-I22
A30: Capex / D&A | C30: =C28/C22 | D30: =D28/D22 | E30: =E28/E22 | F30: =F28/F22 | G30: =G28/G22 | H30: =H28/H22 | I30: =I28/I22
A32: Net working capital | C32: =C11*NWCPct | D32: =D11*NWCPct | E32: =E11*NWCPct | F32: =F11*NWCPct | G32: =G11*NWCPct | H32: =H11*NWCPct | I32: =I11*NWCPct
A33: Increase in net working capital | D33: =D32-C32 | E33: =E32-D32 | F33: =F32-E32 | G33: =G32-F32 | H33: =H32-G32 | I33: =I32-H32
A35: Free cash flow (EBITDA - taxes - capex - increase in NWC) | D35: =D18-D24-D28-D33 | E35: =E18-E24-E28-E33 | F35: =F18-F24-F28-F33 | G35: =G18-G24-G28-G33 | H35: =H18-H24-H28-H33 | I35: =I18-I24-I28-I33
A36: FCF conversion (FCF / EBITDA) | D36: =D35/D18 | E36: =E35/E18 | F36: =F35/F18 | G36: =G35/G18 | H36: =H35/H18 | I36: =I35/I18

Sheet Capex_Report
A1: FY2026 CAPEX: budget vs. year to date vs. forecast
A2: ="Flag when variance is at least "&TEXT(VarPct,"0%")&" and $"&TEXT(VarAmt,"0")&"M. Variance: + = under budget."
A4: Operating company | B4: Maint. budget | C4: Maint. YTD | D4: Maint. forecast | E4: Growth budget | F4: Growth YTD | G4: Growth forecast | H4: Total budget | I4: Total YTD | J4: Total forecast | K4: % of forecast spent | L4: Variance | M4: Variance % | N4: Flag
A5: Aggregates | B5: =Inputs!$O$20 | C5: =Inputs!$P$20 | D5: =OpCo_Plan!D17 | E5: =SUMIF(Projects!$B$5:$B$12,"Aggregates",Projects!$N$5:$N$12) | F5: =SUMIF(Projects!$B$5:$B$12,"Aggregates",Projects!$O$5:$O$12) | G5: =SUMIF(Projects!$B$5:$B$12,"Aggregates",Projects!$P$5:$P$12) | H5: =B5+E5 | I5: =C5+F5 | J5: =D5+G5 | K5: =I5/J5 | L5: =H5-J5 | M5: =L5/H5 | N5: =IF(AND(ABS(M5)>=VarPct,ABS(L5)>=VarAmt),IF(L5>0,"UNDER","OVER"),"")
A6: Cement | B6: =Inputs!$O$21 | C6: =Inputs!$P$21 | D6: =OpCo_Plan!D34 | E6: =SUMIF(Projects!$B$5:$B$12,"Cement",Projects!$N$5:$N$12) | F6: =SUMIF(Projects!$B$5:$B$12,"Cement",Projects!$O$5:$O$12) | G6: =SUMIF(Projects!$B$5:$B$12,"Cement",Projects!$P$5:$P$12) | H6: =B6+E6 | I6: =C6+F6 | J6: =D6+G6 | K6: =I6/J6 | L6: =H6-J6 | M6: =L6/H6 | N6: =IF(AND(ABS(M6)>=VarPct,ABS(L6)>=VarAmt),IF(L6>0,"UNDER","OVER"),"")
A7: Ready-Mix Concrete | B7: =Inputs!$O$22 | C7: =Inputs!$P$22 | D7: =OpCo_Plan!D51 | E7: =SUMIF(Projects!$B$5:$B$12,"Ready-Mix Concrete",Projects!$N$5:$N$12) | F7: =SUMIF(Projects!$B$5:$B$12,"Ready-Mix Concrete",Projects!$O$5:$O$12) | G7: =SUMIF(Projects!$B$5:$B$12,"Ready-Mix Concrete",Projects!$P$5:$P$12) | H7: =B7+E7 | I7: =C7+F7 | J7: =D7+G7 | K7: =I7/J7 | L7: =H7-J7 | M7: =L7/H7 | N7: =IF(AND(ABS(M7)>=VarPct,ABS(L7)>=VarAmt),IF(L7>0,"UNDER","OVER"),"")
A8: Asphalt & Paving | B8: =Inputs!$O$23 | C8: =Inputs!$P$23 | D8: =OpCo_Plan!D68 | E8: =SUMIF(Projects!$B$5:$B$12,"Asphalt & Paving",Projects!$N$5:$N$12) | F8: =SUMIF(Projects!$B$5:$B$12,"Asphalt & Paving",Projects!$O$5:$O$12) | G8: =SUMIF(Projects!$B$5:$B$12,"Asphalt & Paving",Projects!$P$5:$P$12) | H8: =B8+E8 | I8: =C8+F8 | J8: =D8+G8 | K8: =I8/J8 | L8: =H8-J8 | M8: =L8/H8 | N8: =IF(AND(ABS(M8)>=VarPct,ABS(L8)>=VarAmt),IF(L8>0,"UNDER","OVER"),"")
A9: Total | B9: =SUM(B5:B8) | C9: =SUM(C5:C8) | D9: =SUM(D5:D8) | E9: =SUM(E5:E8) | F9: =SUM(F5:F8) | G9: =SUM(G5:G8) | H9: =SUM(H5:H8) | I9: =SUM(I5:I8) | J9: =SUM(J5:J8) | K9: =I9/J9 | L9: =H9-J9 | M9: =L9/H9 | N9: =IF(AND(ABS(M9)>=VarPct,ABS(L9)>=VarAmt),IF(L9>0,"UNDER","OVER"),"")
A11: Five-year CAPEX plan
A12: $ millions | B12: FY2027 | C12: FY2028 | D12: FY2029 | E12: FY2030 | F12: FY2031 | G12: 5-year total | H12: % of total
A13: Aggregates | B13: =OpCo_Plan!E19 | C13: =OpCo_Plan!F19 | D13: =OpCo_Plan!G19 | E13: =OpCo_Plan!H19 | F13: =OpCo_Plan!I19 | G13: =SUM(B13:F13) | H13: =G13/$G$17
A14: Cement | B14: =OpCo_Plan!E36 | C14: =OpCo_Plan!F36 | D14: =OpCo_Plan!G36 | E14: =OpCo_Plan!H36 | F14: =OpCo_Plan!I36 | G14: =SUM(B14:F14) | H14: =G14/$G$17
A15: Ready-Mix Concrete | B15: =OpCo_Plan!E53 | C15: =OpCo_Plan!F53 | D15: =OpCo_Plan!G53 | E15: =OpCo_Plan!H53 | F15: =OpCo_Plan!I53 | G15: =SUM(B15:F15) | H15: =G15/$G$17
A16: Asphalt & Paving | B16: =OpCo_Plan!E70 | C16: =OpCo_Plan!F70 | D16: =OpCo_Plan!G70 | E16: =OpCo_Plan!H70 | F16: =OpCo_Plan!I70 | G16: =SUM(B16:F16) | H16: =G16/$G$17
A17: Total capex | B17: =Consolidation!E28 | C17: =Consolidation!F28 | D17: =Consolidation!G28 | E17: =Consolidation!H28 | F17: =Consolidation!I28 | G17: =SUM(B17:F17) | H17: =G17/$G$17
A18: of which maintenance | B18: =Consolidation!E26 | C18: =Consolidation!F26 | D18: =Consolidation!G26 | E18: =Consolidation!H26 | F18: =Consolidation!I26 | G18: =SUM(B18:F18) | H18: =G18/$G$17
A19: of which growth | B19: =Consolidation!E27 | C19: =Consolidation!F27 | D19: =Consolidation!G27 | E19: =Consolidation!H27 | F19: =Consolidation!I27 | G19: =SUM(B19:F19) | H19: =G19/$G$17
A20: Capex / D&A | B20: =Consolidation!E30 | C20: =Consolidation!F30 | D20: =Consolidation!G30 | E20: =Consolidation!H30 | F20: =Consolidation!I30
A21: Capex % of revenue | B21: =Consolidation!E28/Consolidation!E11 | C21: =Consolidation!F28/Consolidation!F11 | D21: =Consolidation!G28/Consolidation!G11 | E21: =Consolidation!H28/Consolidation!H11 | F21: =Consolidation!I28/Consolidation!I11

Sheet Board_Summary
A1: Granite Peak Materials Group: plan summary for the board
A2: ="Scenario: "&Inputs!$C$3
A4: $ millions | B4: FY2025A | C4: FY2026F | D4: FY2027 Budget | E4: FY2031 Plan | F4: CAGR FY26-31
A5: Revenue | B5: =Consolidation!C11 | C5: =Consolidation!D11 | D5: =Consolidation!E11 | E5: =Consolidation!I11 | F5: =(E5/C5)^(1/5)-1
A6: EBITDA | B6: =Consolidation!C18 | C6: =Consolidation!D18 | D6: =Consolidation!E18 | E6: =Consolidation!I18 | F6: =(E6/C6)^(1/5)-1
A7: EBITDA margin | B7: =Consolidation!C19 | C7: =Consolidation!D19 | D7: =Consolidation!E19 | E7: =Consolidation!I19
A8: Total capex | B8: =Consolidation!C28 | C8: =Consolidation!D28 | D8: =Consolidation!E28 | E8: =Consolidation!I28
A9: Free cash flow | C9: =Consolidation!D35 | D9: =Consolidation!E35 | E9: =Consolidation!I35
A11: 5-year capex FY27-31 | B11: =SUM(Consolidation!E28:Consolidation!I28)
A12: of which growth | B12: =SUM(Consolidation!E27:Consolidation!I27)
A13: 5-year free cash flow FY27-31 | B13: =SUM(Consolidation!E35:Consolidation!I35)
A14: 5-year FCF conversion | B14: =B13/SUM(Consolidation!E18:Consolidation!I18)
A15: Growth projects below hurdle (NPV < 0) | B15: =COUNTIF(Projects!$T$5:$T$12,"<0")
A16: FY2026 capex forecast vs. budget (+ = under) | B16: =Capex_Report!L9
A18: EBITDA bridge FY2026F to FY2031 Plan
A19: Driver | B19: $ millions
A20: FY2026F EBITDA | B20: =Consolidation!D18
A21: Volume | B21: =(OpCo_Plan!I7-OpCo_Plan!D7)*(OpCo_Plan!D9-OpCo_Plan!D11)+(OpCo_Plan!I24-OpCo_Plan!D24)*(OpCo_Plan!D26-OpCo_Plan!D28)+(OpCo_Plan!I41-OpCo_Plan!D41)*(OpCo_Plan!D43-OpCo_Plan!D45)+(OpCo_Plan!I58-OpCo_Plan!D58)*(OpCo_Plan!D60-OpCo_Plan!D62)
A22: Price | B22: =OpCo_Plan!I7*(OpCo_Plan!I9-OpCo_Plan!D9)+OpCo_Plan!I24*(OpCo_Plan!I26-OpCo_Plan!D26)+OpCo_Plan!I41*(OpCo_Plan!I43-OpCo_Plan!D43)+OpCo_Plan!I58*(OpCo_Plan!I60-OpCo_Plan!D60)
A23: Variable cost inflation | B23: =-OpCo_Plan!I7*(OpCo_Plan!I11-OpCo_Plan!D11)+-OpCo_Plan!I24*(OpCo_Plan!I28-OpCo_Plan!D28)+-OpCo_Plan!I41*(OpCo_Plan!I45-OpCo_Plan!D45)+-OpCo_Plan!I58*(OpCo_Plan!I62-OpCo_Plan!D62)
A24: Fixed cost inflation | B24: =-(OpCo_Plan!I13-OpCo_Plan!D13)+-(OpCo_Plan!I30-OpCo_Plan!D30)+-(OpCo_Plan!I47-OpCo_Plan!D47)+-(OpCo_Plan!I64-OpCo_Plan!D64)
A25: Growth projects in service | B25: =(OpCo_Plan!I14-OpCo_Plan!D14)+(OpCo_Plan!I31-OpCo_Plan!D31)+(OpCo_Plan!I48-OpCo_Plan!D48)+(OpCo_Plan!I65-OpCo_Plan!D65)
A26: Corporate costs | B26: =Consolidation!I17-Consolidation!D17
A27: FY2031 Plan EBITDA | B27: =SUM(B20:B26)

Sheet Checks
A1: Integrity checks
A3: Check | B3: Pass? | C3: Difference
A4: Consolidated revenue = operating company revenue - intercompany (all years) | B4: =ABS(C4)<0.001 | C4: =SUM(Consolidation!C11:I11)-((SUM(OpCo_Plan!C10:I10)+SUM(OpCo_Plan!C27:I27)+SUM(OpCo_Plan!C44:I44)+SUM(OpCo_Plan!C61:I61))-(SUM(OpCo_Plan!C10:I10)*Inputs!$N$20+SUM(OpCo_Plan!C27:I27)*Inputs!$N$21+SUM(OpCo_Plan!C44:I44)*Inputs!$N$22+SUM(OpCo_Plan!C61:I61)*Inputs!$N$23))
A5: Consolidated EBITDA = sum of operating company EBITDA + corporate (all years) | B5: =ABS(C5)<0.001 | C5: =SUM(Consolidation!C18:I18)-(SUM(OpCo_Plan!C15:I15)+SUM(OpCo_Plan!C32:I32)+SUM(OpCo_Plan!C49:I49)+SUM(OpCo_Plan!C66:I66)+SUM(Consolidation!C17:I17))
A6: Total capex = maintenance + growth (FY2026-FY2031) | B6: =ABS(C6)<0.001 | C6: =SUM(Consolidation!D28:I28)-SUM(Consolidation!D26:I26)-SUM(Consolidation!D27:I27)
A7: Growth capex in plan = project register spend schedule | B7: =ABS(C7)<0.001 | C7: =SUM(Consolidation!D27:I27)-SUM(Projects!$F$5:$K$12)
A8: PP&E roll-forward: FY2031 = FY2025 + capex - D&A | B8: =ABS(C8)<0.001 | C8: =Consolidation!I29-(PPE2025+SUM(Consolidation!D28:I28)-SUM(Consolidation!D22:I22))
A9: Free cash flow = EBITDA - taxes - capex - increase in NWC (FY2026-FY2031) | B9: =ABS(C9)<0.001 | C9: =SUM(Consolidation!D35:I35)-(SUM(Consolidation!D18:I18)-SUM(Consolidation!D24:I24)-SUM(Consolidation!D28:I28)-SUM(Consolidation!D33:I33))
A10: EBITDA bridge ends at FY2031 Plan EBITDA | B10: =ABS(C10)<0.001 | C10: =Board_Summary!B27-Consolidation!I18
A11: FY2026 capex report forecast = consolidated FY2026 capex | B11: =ABS(C11)<0.001 | C11: =Capex_Report!J9-Consolidation!D28
A12: Project forecast totals = sum of yearly schedule | B12: =ABS(C12)<0.001 | C12: =SUM(Projects!$L$5:$L$12)-SUM(Projects!$F$5:$K$12)
A13: Scenario selector is 1, 2 or 3 | B13: =OR(Scenario=1,Scenario=2,Scenario=3)
A14: ALL CHECKS PASS | B14: =AND(B4:B13)
